<?xml version="1.0" ?>
<!-- =================================================================================== -->
<!-- |    This document was autogenerated by xacro from miabot.xacro                   | -->
<!-- |    EDITING THIS FILE BY HAND IS NOT RECOMMENDED                                 | -->
<!-- =================================================================================== -->
<!-- Miabot PRO - Miniature Intelligent Autonomous roBOT -->
<!-- Merlin Systems Corp. Ltd -->
<!-- www.merlinsytsemscorp.co.uk -->
<!-- Author: Mark Norman 8th January 2011 -->
<!-- Exapnsion kit definitions to follow: Sonar, Compass, Gripper, OnBoard Camera-->
<!--                                      Kinect, Line Follower -->
<robot name="miabot" xmlns:body="http://playerstage.sourceforge.net/gazebo/xmlschema/#body" xmlns:controller="http://playerstage.sourceforge.net/gazebo/xmlschema/#controller" xmlns:gazebo="http://playerstage.sourceforge.net/gazebo/xmlschema/#gz" xmlns:geom="http://playerstage.sourceforge.net/gazebo/xmlschema/#geom" xmlns:interface="http://playerstage.sourceforge.net/gazebo/xmlschema/#interface" xmlns:joint="http://playerstage.sourceforge.net/gazebo/xmlschema/#joint" xmlns:model="http://playerstage.sourceforge.net/gazebo/xmlschema/#model" xmlns:physics="http://playerstage.sourceforge.net/gazebo/xmlschema/#physics" xmlns:renderable="http://playerstage.sourceforge.net/gazebo/xmlschema/#renderable" xmlns:rendering="http://playerstage.sourceforge.net/gazebo/xmlschema/#rendering" xmlns:sensor="http://playerstage.sourceforge.net/gazebo/xmlschema/#sensor" xmlns:xacro="http://www.ros.org/wiki/xacro" xmlns:xi="http://www.w3.org/2001/XInclude">
  <!-- Links: inertial,visual,collision -->
  <link name="base_link">
    <inertial>
      <!-- origin is relative -->
      <origin rpy="0 0 0" xyz="0 0 0"/>
      <mass value="5"/>
      <inertia ixx="5" ixy="0" ixz="0" iyy="5" iyz="0" izz="5"/>
    </inertial>
    <visual>
      <origin rpy="0 0 0" xyz="0 0 0.003"/>
      <geometry>
        <box size="0.07 0.07 0.07"/>
      </geometry>
      <material name="black">
        <color rgba="0 0 0 0"/>
      </material>
    </visual>
    <collision>
      <geometry>
        <box size="0.07 0.07 0.07"/>
      </geometry>
    </collision>
  </link>
  <link name="left_wheel" params="r g b">
    <inertial>
      <origin rpy="0 0 0" xyz="0 0 0"/>
      <mass value="1"/>
      <inertia ixx="0.2" ixy="0" ixz="0" iyy="0.2" iyz="0" izz="0.2"/>
    </inertial>
    <visual>
      <origin rpy="0 1.57 1.57" xyz="0 0 0"/>
      <geometry>
        <cylinder length="0.01" radius="0.025"/>
      </geometry>
      <material name="white">
        <color rgba="1 1 1 1"/>
      </material>
    </visual>
  </link>
  <link name="right_wheel" params="r g b">
    <inertial>
      <origin rpy="0 0 0" xyz="0 0 0"/>
      <mass value="1"/>
      <inertia ixx="0.2" ixy="0" ixz="0" iyy="0.2" iyz="0" izz="0.2"/>
    </inertial>
    <visual>
      <origin rpy="0 1.57 1.57" xyz="0 0 0"/>
      <geometry>
        <cylinder length="0.01" radius="0.025"/>
      </geometry>
      <material name="white">
        <color rgba="1 1 1 1"/>
      </material>
    </visual>
  </link>
  <joint name="left_joint" type="continuous">
    <parent link="base_link"/>
    <child b="1" g="1" link="left_wheel" r="1"/>
    <origin xyz="0 -0.035 -0.01"/>
    <axis xyz="1 0 0"/>
    <limit effort="100" velocity="100"/>
    <joint_properties damping="0.0" friction="0.0"/>
  </joint>
  <joint name="right_joint" type="continuous">
    <parent link="base_link"/>
    <child b="1" g="1" link="right_wheel" r="1"/>
    <origin xyz="0 0.035 -0.01"/>
    <axis xyz="1 0 0"/>
    <limit effort="100" velocity="100"/>
    <joint_properties damping="0.0" friction="0.0"/>
  </joint>
  <transmission name="left_joint_trans" type="SimpleTransmission">
    <actuator name="left_joint_motor"/>
    <joint name="{$prefix}_joint"/>
    <mechanicalReduction>1</mechanicalReduction>
    <motorTorqueConstant>1</motorTorqueConstant>
  </transmission>
  <transmission name="right_joint_trans" type="SimpleTransmission">
    <actuator name="right_joint_motor"/>
    <joint name="{$prefix}_joint"/>
    <mechanicalReduction>1</mechanicalReduction>
    <motorTorqueConstant>1</motorTorqueConstant>
  </transmission>
  <!-- Colour -->
  <gazebo reference="base_link">
    <material>Gazebo/Green</material>
  </gazebo>
  <gazebo reference="left_wheel">
    <material>Gazebo/Red</material>
  </gazebo>
  <gazebo reference="right_wheel">
    <material>Gazebo/Blue</material>
  </gazebo>
</robot>

